<?xml version="1.0"?>

<robot name="barista_robot">

<link name="base_footprint"/>
  
    <joint name="base_joint" type="fixed">
        <parent link="base_footprint"/>
        <child link="base_link"/>
        <origin xyz="0.0 0.0 0.0" rpy="0 0 0"/>
    </joint> 

    <!-- Base link -->
    <link name="base_link">
        <visual>
            <geometry>
                <cylinder length="0.155" radius="0.178"></cylinder> <!-- Adjust dimensions -->
            </geometry>
        </visual>
        <collision>
            <geometry>
                <cylinder length="0.155" radius="0.178"></cylinder> <!-- Adjust dimensions -->
            </geometry>
        </collision>
        <inertial>
            <mass value="10"/>
            <origin xyz="0 0 0" rpy="0 0 0"/>
            <inertia ixx="0.099" ixy="0" ixz="0" iyy="0.099" iyz="0" izz="0.158"/>
        </inertial>
    </link>

    <!-- Laser scanner -->
    <link name="laser_link">
        <visual>
            <origin rpy="0 0 0" xyz="0 0 0"/>
            <geometry>
                <mesh 
                  filename="package://barista_robot_description/meshes/hokuyo3d.dae" />
            </geometry>
        </visual>
        <collision>
            <geometry>
                <cylinder length="0.0206" radius="0.0352"></cylinder>
            </geometry>
        </collision>
        <inertial>
            <origin xyz="0 0 0"/> <!-- Center of mass -->
            <mass value="0.01"/>
            <inertia ixx="0.0001339" ixy="0" ixz="0" iyy="0.0001339" iyz="0" izz="0.000001125"/>
        </inertial>
    </link>
    <joint name="base_to_laser" type="fixed">
        <parent link="base_link"/>
        <child link="laser_link"/>
        <origin xyz="0 0 0.08"/> <!-- Adjust position -->
    </joint>

    <!-- Standoffs -->
    <link name="standoff1">
        <visual>
            <geometry>
                <cylinder length="0.220" radius="0.01"/>
            </geometry>
            <origin rpy="0 0 0" xyz="0 0 0" />
        </visual>
        <collision>
            <geometry>
                <cylinder length="0.220" radius="0.01"/>
            </geometry>
            <origin rpy="0 0 0" xyz="0 0 0" />
        </collision>
        <inertial>
            <origin rpy="0 0 0" xyz="0 0 0"/>
            <mass value="0.05"/>
            <inertia ixx="0.0002029" ixy="0" ixz="0" iyy="0.0002029" iyz="0" izz="0.0000025"/>
        </inertial>
    </link>
    <joint name="standoff1_joint" type="fixed">
        <origin rpy="0 0 0" xyz="0.05 0.14 0.1875" />
        <parent link="base_link" />
        <child link="standoff1" />
    </joint>

    <link name="standoff2">
        <visual>
            <geometry>
                <cylinder length="0.220" radius="0.01"/>
            </geometry>
            <origin rpy="0 0 0" xyz="0 0 0" />
        </visual>
        <collision>
            <geometry>
                <cylinder length="0.220" radius="0.01"/>
            </geometry>
            <origin rpy="0 0 0" xyz="0 0 0" />
        </collision>
        <inertial>
            <origin rpy="0 0 0" xyz="0 0 0"/>
            <mass value="0.05"/>
            <inertia ixx="0.0002029" ixy="0" ixz="0" iyy="0.0002029" iyz="0" izz="0.0000025"/>
        </inertial>
    </link>
    <joint name="standoff2_joint" type="fixed">
        <origin rpy="0 0 0" xyz="-0.05 0.14 0.1875" />
        <parent link="base_link" />
        <child link="standoff2" />
    </joint>

    <link name="standoff3">
        <visual>
            <geometry>
                <cylinder length="0.220" radius="0.01"/>
            </geometry>
            <origin rpy="0 0 0" xyz="0 0 0" />
        </visual>
        <collision>
            <geometry>
                <cylinder length="0.220" radius="0.01"/>
            </geometry>
            <origin rpy="0 0 0" xyz="0 0 0" />
        </collision>
        <inertial>
            <origin rpy="0 0 0" xyz="0 0 0"/>
            <mass value="0.05"/>
            <inertia ixx="0.0002029" ixy="0" ixz="0" iyy="0.0002029" iyz="0" izz="0.0000025"/>
        </inertial>
    </link>
    <joint name="standoff3_joint" type="fixed">
        <origin rpy="0 0 0" xyz="0.05 -0.14 0.1875" />
        <parent link="base_link" />
        <child link="standoff3" />
    </joint>

    <link name="standoff4">
        <visual>
            <geometry>
                <cylinder length="0.220" radius="0.01"/>
            </geometry>
            <origin rpy="0 0 0" xyz="0 0 0" />
        </visual>
        <collision>
            <geometry>
                <cylinder length="0.220" radius="0.01"/>
            </geometry>
            <origin rpy="0 0 0" xyz="0 0 0" />
        </collision>
        <inertial>
            <origin rpy="0 0 0" xyz="0 0 0"/>
            <mass value="0.05"/>
            <inertia ixx="0.0002029" ixy="0" ixz="0" iyy="0.0002029" iyz="0" izz="0.0000025"/>
        </inertial>
    </link>
    <joint name="standoff4_joint" type="fixed">
        <origin rpy="0 0 0" xyz="-0.05 -0.14 0.1875" />
        <parent link="base_link" />
        <child link="standoff4" />
    </joint>

    <!-- cup tray -->
    <link name="cup_tray">
        <visual>
            <geometry>
                <cylinder length="0.090" radius="0.160"/>
            </geometry>
            <origin rpy="0 0 0" xyz="0 0 0.045" />
        </visual>
        <collision>
            <geometry>
                <cylinder length="0.090" radius="0.160"/>
            </geometry>
            <origin rpy="0 0 0" xyz="0 0 0.045" />
        </collision>
        <inertial>
            <mass value="0.1"/>
            <origin rpy="0 0 0" xyz="0 0 0.045" />
            <inertia ixx="0.0007075" ixy="0" ixz="0" iyy="0.0007075" iyz="0" izz="0.00128"/>
        </inertial>
    </link>
    <joint name="cup_tray_joint" type="fixed">
        <origin rpy="0 0 0" xyz="0 0 0.2975" />
        <parent link="base_link" />
        <child link="cup_tray" />
    </joint>

  <!-- wheels -->
    <link name="wheel_right">
        <visual>
            <geometry>
                <cylinder length="0.0206" radius="0.0352"/>
            </geometry>
            <origin rpy="1.5707 0 0" xyz="0 0 0"/>
        </visual>
        <collision>
            <geometry>
                <cylinder length="0.0206" radius="0.0352"/>
            </geometry>
            <origin rpy="1.5707 0 0" xyz="0 0 0"/>
        </collision>
        <inertial>
            <origin
                    xyz="0 0 0"
                    rpy="0 0 0" />
             <mass value="1.12009995547518" />
             <inertia
                    ixx="0.00264995117951638"
                    ixy="1.2635808076617E-09"
                    ixz="8.81688298807932E-08"
                    iyy="0.00496694769533462"
                    iyz="-8.07547875661367E-09"
                    izz="0.0026499921267862" />
        </inertial>
    </link>
    <joint name="wheel_right_joint" type="continuous">
        <origin rpy="0 0 0" xyz="0 -0.15 -0.0775" />
        <parent link="base_link" />
        <child link="wheel_right" />
        <axis rpy="0 0 0" xyz="0 1 0"/>
        <limit effort="10000" velocity="1000"/>
        <joint_properties damping="1.0" friction="1.0"/>
    </joint>

    <link name="wheel_left">
        <visual>
            <geometry>
                <cylinder length="0.0206" radius="0.0352"/>
            </geometry>
            <origin rpy="1.5707 0 0" xyz="0 0 0"/>
        </visual>
        <collision>
            <geometry>
                <cylinder length="0.0206" radius="0.0352"/>
            </geometry>
            <origin rpy="1.5707 0 0" xyz="0 0 0"/>
        </collision>
        <inertial>
            <origin
                    xyz="0 0 0"
                    rpy="0 0 0" />
             <mass value="1.12009995547518" />
             <inertia
                    ixx="0.00264995117951638"
                    ixy="1.2635808076617E-09"
                    ixz="8.81688298807932E-08"
                    iyy="0.00496694769533462"
                    iyz="-8.07547875661367E-09"
                    izz="0.0026499921267862" />
        </inertial>
    </link>
    <joint name="wheel_left_joint" type="continuous">
        <origin rpy="0 0 0" xyz="0 0.15 -0.0775" />
        <parent link="base_link" />
        <child link="wheel_left" />
        <axis rpy="0 0 0" xyz="0 1 0"/>
        <limit effort="10000" velocity="1000"/>
        <joint_properties damping="1.0" friction="1.0"/>
    </joint>

    <link name="caster_front">
        <visual>
            <geometry>
                <sphere radius="0.0252"/>
            </geometry>
        </visual>
        <visual>
            <origin rpy="0 0 0" xyz="0 0 -0.0252"/>
            <geometry>
                <sphere radius="0.01"/>
            </geometry>
        </visual>
        <collision>
            <geometry>
                <sphere radius="0.0352"/>
            </geometry>
        </collision>
        <inertial>
            <mass value="0.01"/>
            <origin rpy="0 1.5707 1.5707" xyz="0 0 0"/>
            <inertia ixx="0.000004234" ixy="0" ixz="0" iyy="0.000004234" iyz="0" izz="0.000004234"/>
        </inertial>
    </link>
    <joint name="caster_front_joint" type="fixed">
        <origin rpy="0 0 0" xyz="0.133 0 -0.0775" />
        <parent link="base_link" />
        <child link="caster_front" />
    </joint>

    <link name="caster_rear">
        <visual>
            <geometry>
                <sphere radius="0.0252"/>
            </geometry>
        </visual>
        <visual>
            <origin rpy="0 0 0" xyz="0 0 -0.0252"/>
            <geometry>
                <sphere radius="0.01"/>
            </geometry>
        </visual>
        <collision>
            <geometry>
                <sphere radius="0.0352"/>
            </geometry>
        </collision>
        <inertial>
            <mass value="0.1"/>
            <origin rpy="0 0 0" xyz="0 0 0"/>
            <inertia ixx="0.000004234" ixy="0" ixz="0" iyy="0.000004234" iyz="0" izz="0.000004234"/>
        </inertial>
    </link>
    <joint name="caster_rear_joint" type="fixed">
        <origin rpy="0 0 0" xyz="-0.133 0 -0.0775" />
        <parent link="base_link" />
        <child link="caster_rear" />
    </joint>


    <!-- Laser scan plugin -->
    <gazebo reference="laser_link">
        <sensor name="sensor_ray" type="ray">
            <pose>0.0615 0 0.085 0 0 0</pose>
            <ray>
            <scan>
                <horizontal>
                <samples>360</samples>
                <resolution>1.0</resolution>
                <min_angle>-3.14</min_angle>
                <max_angle>3.14</max_angle>
                </horizontal>
            </scan>
            <range>
                <min>0.2</min>
                <max>10</max>
            </range>
            </ray>
            <always_on>true</always_on>
            <visualize>false</visualize>
            <update_rate>10.0</update_rate>
            <plugin name="laser" filename="libgazebo_ros_ray_sensor.so">
            <ros>
                <remapping>~/out:=/scan</remapping>
            </ros>
            <output_type>sensor_msgs/LaserScan</output_type>
            </plugin>
        </sensor>
    </gazebo>

    <gazebo>
        <plugin filename="libgazebo_ros_diff_drive.so" name="differential_drive_controller">

        <!-- wheels -->
        <left_joint>wheel_left_joint</left_joint>
        <right_joint>wheel_right_joint</right_joint>

        <!-- kinematics -->
        <wheel_separation>0.3</wheel_separation>
        <wheel_diameter>0.0704</wheel_diameter>

        <!-- limits -->
        <max_wheel_torque>1.0</max_wheel_torque>
        <max_wheel_acceleration>2.0</max_wheel_acceleration>

        <!-- output -->
        <publish_odom>true</publish_odom>
        <publish_odom_tf>true</publish_odom_tf>

        <odometry_frame>odom</odometry_frame>
        <robot_base_frame>base_footprint</robot_base_frame>

        </plugin>
    </gazebo>

    <gazebo>
    <plugin name="box_bot_joint_state" filename="libgazebo_ros_joint_state_publisher.so">
      <ros>
          <namespace>/${robot_name}</namespace>
          <remapping>~/out:=joint_states</remapping>
      </ros>
      <update_rate>30</update_rate>

      <joint_name>wheel_left_joint</joint_name>
      <joint_name>wheel_right_joint</joint_name>

      
    </plugin>
  </gazebo>

</robot>